2022-01-12 07:56:13,160:ERROR:main:Exception occurred in the function 'rec_imp_features'. Exception message: [Errno 2] No such file or directory: 'results/relevant_features_by_models.csv'
Traceback (most recent call last):
  File "C:/Users/GOQii-BhushanP/PycharmProjects/CementStregthDetection/main.py", line 79, in rec_imp_features
    return dataframe.to_csv('results/relevant_features_by_models.csv', index=False)
  File "C:\Users\GOQii-BhushanP\anaconda3\envs\CementStregthDetection\lib\site-packages\pandas\core\generic.py", line 3482, in to_csv
    storage_options=storage_options,
  File "C:\Users\GOQii-BhushanP\anaconda3\envs\CementStregthDetection\lib\site-packages\pandas\io\formats\format.py", line 1105, in to_csv
    csv_formatter.save()
  File "C:\Users\GOQii-BhushanP\anaconda3\envs\CementStregthDetection\lib\site-packages\pandas\io\formats\csvs.py", line 243, in save
    storage_options=self.storage_options,
  File "C:\Users\GOQii-BhushanP\anaconda3\envs\CementStregthDetection\lib\site-packages\pandas\io\common.py", line 707, in get_handle
    newline="",
FileNotFoundError: [Errno 2] No such file or directory: 'results/relevant_features_by_models.csv'
2022-01-12 07:56:13,172:ERROR:main:Defining a function "evaluate" to evaluate the performance metrics of a model
NoneType: None
2022-01-12 07:57:21,649:ERROR:main:Exception occurred in the function 'rec_imp_features'. Exception message: [Errno 2] No such file or directory: 'results/relevant_features_by_models.csv'
Traceback (most recent call last):
  File "C:/Users/GOQii-BhushanP/PycharmProjects/CementStregthDetection/main.py", line 79, in rec_imp_features
    return dataframe.to_csv('results/relevant_features_by_models.csv', index=False)
  File "C:\Users\GOQii-BhushanP\anaconda3\envs\CementStregthDetection\lib\site-packages\pandas\core\generic.py", line 3482, in to_csv
    storage_options=storage_options,
  File "C:\Users\GOQii-BhushanP\anaconda3\envs\CementStregthDetection\lib\site-packages\pandas\io\formats\format.py", line 1105, in to_csv
    csv_formatter.save()
  File "C:\Users\GOQii-BhushanP\anaconda3\envs\CementStregthDetection\lib\site-packages\pandas\io\formats\csvs.py", line 243, in save
    storage_options=self.storage_options,
  File "C:\Users\GOQii-BhushanP\anaconda3\envs\CementStregthDetection\lib\site-packages\pandas\io\common.py", line 707, in get_handle
    newline="",
FileNotFoundError: [Errno 2] No such file or directory: 'results/relevant_features_by_models.csv'
2022-01-12 07:57:21,649:ERROR:main:Defining a function "evaluate" to evaluate the performance metrics of a model
NoneType: None
2022-01-12 07:57:21,649:ERROR:main:Exception occurred in the function 'evaluate'. Exception message: adj_r2_score() takes 3 positional arguments but 4 were given
Traceback (most recent call last):
  File "C:/Users/GOQii-BhushanP/PycharmProjects/CementStregthDetection/main.py", line 125, in evaluate
    metrics.adj_r2_score(x_train, y_train, y_pred_train),
TypeError: adj_r2_score() takes 3 positional arguments but 4 were given
2022-01-12 07:57:21,699:ERROR:main:Exception occurred in the function 'rec_imp_features'. Exception message: [Errno 2] No such file or directory: 'results/relevant_features_by_models.csv'
Traceback (most recent call last):
  File "C:/Users/GOQii-BhushanP/PycharmProjects/CementStregthDetection/main.py", line 79, in rec_imp_features
    return dataframe.to_csv('results/relevant_features_by_models.csv', index=False)
  File "C:\Users\GOQii-BhushanP\anaconda3\envs\CementStregthDetection\lib\site-packages\pandas\core\generic.py", line 3482, in to_csv
    storage_options=storage_options,
  File "C:\Users\GOQii-BhushanP\anaconda3\envs\CementStregthDetection\lib\site-packages\pandas\io\formats\format.py", line 1105, in to_csv
    csv_formatter.save()
  File "C:\Users\GOQii-BhushanP\anaconda3\envs\CementStregthDetection\lib\site-packages\pandas\io\formats\csvs.py", line 243, in save
    storage_options=self.storage_options,
  File "C:\Users\GOQii-BhushanP\anaconda3\envs\CementStregthDetection\lib\site-packages\pandas\io\common.py", line 707, in get_handle
    newline="",
FileNotFoundError: [Errno 2] No such file or directory: 'results/relevant_features_by_models.csv'
2022-01-12 07:57:21,714:ERROR:main:Exception occurred in the function 'evaluate'. Exception message: adj_r2_score() takes 3 positional arguments but 4 were given
Traceback (most recent call last):
  File "C:/Users/GOQii-BhushanP/PycharmProjects/CementStregthDetection/main.py", line 125, in evaluate
    metrics.adj_r2_score(x_train, y_train, y_pred_train),
TypeError: adj_r2_score() takes 3 positional arguments but 4 were given
2022-01-12 07:57:21,763:ERROR:main:Exception occurred in the function 'rec_imp_features'. Exception message: [Errno 2] No such file or directory: 'results/relevant_features_by_models.csv'
Traceback (most recent call last):
  File "C:/Users/GOQii-BhushanP/PycharmProjects/CementStregthDetection/main.py", line 79, in rec_imp_features
    return dataframe.to_csv('results/relevant_features_by_models.csv', index=False)
  File "C:\Users\GOQii-BhushanP\anaconda3\envs\CementStregthDetection\lib\site-packages\pandas\core\generic.py", line 3482, in to_csv
    storage_options=storage_options,
  File "C:\Users\GOQii-BhushanP\anaconda3\envs\CementStregthDetection\lib\site-packages\pandas\io\formats\format.py", line 1105, in to_csv
    csv_formatter.save()
  File "C:\Users\GOQii-BhushanP\anaconda3\envs\CementStregthDetection\lib\site-packages\pandas\io\formats\csvs.py", line 243, in save
    storage_options=self.storage_options,
  File "C:\Users\GOQii-BhushanP\anaconda3\envs\CementStregthDetection\lib\site-packages\pandas\io\common.py", line 707, in get_handle
    newline="",
FileNotFoundError: [Errno 2] No such file or directory: 'results/relevant_features_by_models.csv'
2022-01-12 07:57:21,763:ERROR:main:Exception occurred in the function 'evaluate'. Exception message: adj_r2_score() takes 3 positional arguments but 4 were given
Traceback (most recent call last):
  File "C:/Users/GOQii-BhushanP/PycharmProjects/CementStregthDetection/main.py", line 125, in evaluate
    metrics.adj_r2_score(x_train, y_train, y_pred_train),
TypeError: adj_r2_score() takes 3 positional arguments but 4 were given
2022-01-12 07:58:10,297:ERROR:main:Exception occurred in the function 'rec_imp_features'. Exception message: [Errno 2] No such file or directory: 'results/relevant_features_by_models.csv'
Traceback (most recent call last):
  File "C:/Users/GOQii-BhushanP/PycharmProjects/CementStregthDetection/main.py", line 79, in rec_imp_features
    return dataframe.to_csv('results/relevant_features_by_models.csv', index=False)
  File "C:\Users\GOQii-BhushanP\anaconda3\envs\CementStregthDetection\lib\site-packages\pandas\core\generic.py", line 3482, in to_csv
    storage_options=storage_options,
  File "C:\Users\GOQii-BhushanP\anaconda3\envs\CementStregthDetection\lib\site-packages\pandas\io\formats\format.py", line 1105, in to_csv
    csv_formatter.save()
  File "C:\Users\GOQii-BhushanP\anaconda3\envs\CementStregthDetection\lib\site-packages\pandas\io\formats\csvs.py", line 243, in save
    storage_options=self.storage_options,
  File "C:\Users\GOQii-BhushanP\anaconda3\envs\CementStregthDetection\lib\site-packages\pandas\io\common.py", line 707, in get_handle
    newline="",
FileNotFoundError: [Errno 2] No such file or directory: 'results/relevant_features_by_models.csv'
2022-01-12 07:58:10,297:ERROR:main:Defining a function "evaluate" to evaluate the performance metrics of a model
NoneType: None
2022-01-12 07:58:10,297:ERROR:main:Exception occurred in the function 'evaluate'. Exception message: adj_r2_score() takes 3 positional arguments but 4 were given
Traceback (most recent call last):
  File "C:/Users/GOQii-BhushanP/PycharmProjects/CementStregthDetection/main.py", line 125, in evaluate
    metrics.adj_r2_score(x_train, y_train, y_pred_train),
TypeError: adj_r2_score() takes 3 positional arguments but 4 were given
2022-01-12 07:58:10,355:ERROR:main:Exception occurred in the function 'rec_imp_features'. Exception message: [Errno 2] No such file or directory: 'results/relevant_features_by_models.csv'
Traceback (most recent call last):
  File "C:/Users/GOQii-BhushanP/PycharmProjects/CementStregthDetection/main.py", line 79, in rec_imp_features
    return dataframe.to_csv('results/relevant_features_by_models.csv', index=False)
  File "C:\Users\GOQii-BhushanP\anaconda3\envs\CementStregthDetection\lib\site-packages\pandas\core\generic.py", line 3482, in to_csv
    storage_options=storage_options,
  File "C:\Users\GOQii-BhushanP\anaconda3\envs\CementStregthDetection\lib\site-packages\pandas\io\formats\format.py", line 1105, in to_csv
    csv_formatter.save()
  File "C:\Users\GOQii-BhushanP\anaconda3\envs\CementStregthDetection\lib\site-packages\pandas\io\formats\csvs.py", line 243, in save
    storage_options=self.storage_options,
  File "C:\Users\GOQii-BhushanP\anaconda3\envs\CementStregthDetection\lib\site-packages\pandas\io\common.py", line 707, in get_handle
    newline="",
FileNotFoundError: [Errno 2] No such file or directory: 'results/relevant_features_by_models.csv'
2022-01-12 07:58:10,356:ERROR:main:Exception occurred in the function 'evaluate'. Exception message: adj_r2_score() takes 3 positional arguments but 4 were given
Traceback (most recent call last):
  File "C:/Users/GOQii-BhushanP/PycharmProjects/CementStregthDetection/main.py", line 125, in evaluate
    metrics.adj_r2_score(x_train, y_train, y_pred_train),
TypeError: adj_r2_score() takes 3 positional arguments but 4 were given
2022-01-12 07:58:10,409:ERROR:main:Exception occurred in the function 'rec_imp_features'. Exception message: [Errno 2] No such file or directory: 'results/relevant_features_by_models.csv'
Traceback (most recent call last):
  File "C:/Users/GOQii-BhushanP/PycharmProjects/CementStregthDetection/main.py", line 79, in rec_imp_features
    return dataframe.to_csv('results/relevant_features_by_models.csv', index=False)
  File "C:\Users\GOQii-BhushanP\anaconda3\envs\CementStregthDetection\lib\site-packages\pandas\core\generic.py", line 3482, in to_csv
    storage_options=storage_options,
  File "C:\Users\GOQii-BhushanP\anaconda3\envs\CementStregthDetection\lib\site-packages\pandas\io\formats\format.py", line 1105, in to_csv
    csv_formatter.save()
  File "C:\Users\GOQii-BhushanP\anaconda3\envs\CementStregthDetection\lib\site-packages\pandas\io\formats\csvs.py", line 243, in save
    storage_options=self.storage_options,
  File "C:\Users\GOQii-BhushanP\anaconda3\envs\CementStregthDetection\lib\site-packages\pandas\io\common.py", line 707, in get_handle
    newline="",
FileNotFoundError: [Errno 2] No such file or directory: 'results/relevant_features_by_models.csv'
2022-01-12 07:58:10,409:ERROR:main:Exception occurred in the function 'evaluate'. Exception message: adj_r2_score() takes 3 positional arguments but 4 were given
Traceback (most recent call last):
  File "C:/Users/GOQii-BhushanP/PycharmProjects/CementStregthDetection/main.py", line 125, in evaluate
    metrics.adj_r2_score(x_train, y_train, y_pred_train),
TypeError: adj_r2_score() takes 3 positional arguments but 4 were given
2022-01-12 07:59:27,852:ERROR:main:Exception occurred in the function 'rec_imp_features'. Exception message: [Errno 2] No such file or directory: 'results/relevant_features_by_models.csv'
Traceback (most recent call last):
  File "C:/Users/GOQii-BhushanP/PycharmProjects/CementStregthDetection/main.py", line 79, in rec_imp_features
    return dataframe.to_csv('results/relevant_features_by_models.csv', index=False)
  File "C:\Users\GOQii-BhushanP\anaconda3\envs\CementStregthDetection\lib\site-packages\pandas\core\generic.py", line 3482, in to_csv
    storage_options=storage_options,
  File "C:\Users\GOQii-BhushanP\anaconda3\envs\CementStregthDetection\lib\site-packages\pandas\io\formats\format.py", line 1105, in to_csv
    csv_formatter.save()
  File "C:\Users\GOQii-BhushanP\anaconda3\envs\CementStregthDetection\lib\site-packages\pandas\io\formats\csvs.py", line 243, in save
    storage_options=self.storage_options,
  File "C:\Users\GOQii-BhushanP\anaconda3\envs\CementStregthDetection\lib\site-packages\pandas\io\common.py", line 707, in get_handle
    newline="",
FileNotFoundError: [Errno 2] No such file or directory: 'results/relevant_features_by_models.csv'
2022-01-12 07:59:27,852:ERROR:main:Defining a function "evaluate" to evaluate the performance metrics of a model
NoneType: None
2022-01-12 07:59:27,852:ERROR:main:Exception occurred in the function 'evaluate'. Exception message: adj_r2_score() takes 3 positional arguments but 4 were given
Traceback (most recent call last):
  File "C:/Users/GOQii-BhushanP/PycharmProjects/CementStregthDetection/main.py", line 125, in evaluate
    metrics.adj_r2_score(x_train, y_train, y_pred_train),
TypeError: adj_r2_score() takes 3 positional arguments but 4 were given
2022-01-12 07:59:27,902:ERROR:main:Exception occurred in the function 'rec_imp_features'. Exception message: [Errno 2] No such file or directory: 'results/relevant_features_by_models.csv'
Traceback (most recent call last):
  File "C:/Users/GOQii-BhushanP/PycharmProjects/CementStregthDetection/main.py", line 79, in rec_imp_features
    return dataframe.to_csv('results/relevant_features_by_models.csv', index=False)
  File "C:\Users\GOQii-BhushanP\anaconda3\envs\CementStregthDetection\lib\site-packages\pandas\core\generic.py", line 3482, in to_csv
    storage_options=storage_options,
  File "C:\Users\GOQii-BhushanP\anaconda3\envs\CementStregthDetection\lib\site-packages\pandas\io\formats\format.py", line 1105, in to_csv
    csv_formatter.save()
  File "C:\Users\GOQii-BhushanP\anaconda3\envs\CementStregthDetection\lib\site-packages\pandas\io\formats\csvs.py", line 243, in save
    storage_options=self.storage_options,
  File "C:\Users\GOQii-BhushanP\anaconda3\envs\CementStregthDetection\lib\site-packages\pandas\io\common.py", line 707, in get_handle
    newline="",
FileNotFoundError: [Errno 2] No such file or directory: 'results/relevant_features_by_models.csv'
2022-01-12 07:59:27,902:ERROR:main:Exception occurred in the function 'evaluate'. Exception message: adj_r2_score() takes 3 positional arguments but 4 were given
Traceback (most recent call last):
  File "C:/Users/GOQii-BhushanP/PycharmProjects/CementStregthDetection/main.py", line 125, in evaluate
    metrics.adj_r2_score(x_train, y_train, y_pred_train),
TypeError: adj_r2_score() takes 3 positional arguments but 4 were given
2022-01-12 07:59:27,948:ERROR:main:Exception occurred in the function 'rec_imp_features'. Exception message: [Errno 2] No such file or directory: 'results/relevant_features_by_models.csv'
Traceback (most recent call last):
  File "C:/Users/GOQii-BhushanP/PycharmProjects/CementStregthDetection/main.py", line 79, in rec_imp_features
    return dataframe.to_csv('results/relevant_features_by_models.csv', index=False)
  File "C:\Users\GOQii-BhushanP\anaconda3\envs\CementStregthDetection\lib\site-packages\pandas\core\generic.py", line 3482, in to_csv
    storage_options=storage_options,
  File "C:\Users\GOQii-BhushanP\anaconda3\envs\CementStregthDetection\lib\site-packages\pandas\io\formats\format.py", line 1105, in to_csv
    csv_formatter.save()
  File "C:\Users\GOQii-BhushanP\anaconda3\envs\CementStregthDetection\lib\site-packages\pandas\io\formats\csvs.py", line 243, in save
    storage_options=self.storage_options,
  File "C:\Users\GOQii-BhushanP\anaconda3\envs\CementStregthDetection\lib\site-packages\pandas\io\common.py", line 707, in get_handle
    newline="",
FileNotFoundError: [Errno 2] No such file or directory: 'results/relevant_features_by_models.csv'
2022-01-12 07:59:27,948:ERROR:main:Exception occurred in the function 'evaluate'. Exception message: adj_r2_score() takes 3 positional arguments but 4 were given
Traceback (most recent call last):
  File "C:/Users/GOQii-BhushanP/PycharmProjects/CementStregthDetection/main.py", line 125, in evaluate
    metrics.adj_r2_score(x_train, y_train, y_pred_train),
TypeError: adj_r2_score() takes 3 positional arguments but 4 were given
2022-01-12 08:02:07,316:ERROR:main:Exception occurred in the function 'rec_imp_features'. Exception message: [Errno 2] No such file or directory: 'results/relevant_features_by_models.csv'
Traceback (most recent call last):
  File "C:/Users/GOQii-BhushanP/PycharmProjects/CementStregthDetection/main.py", line 79, in rec_imp_features
    return dataframe.to_csv('results/relevant_features_by_models.csv', index=False)
  File "C:\Users\GOQii-BhushanP\anaconda3\envs\CementStregthDetection\lib\site-packages\pandas\core\generic.py", line 3482, in to_csv
    storage_options=storage_options,
  File "C:\Users\GOQii-BhushanP\anaconda3\envs\CementStregthDetection\lib\site-packages\pandas\io\formats\format.py", line 1105, in to_csv
    csv_formatter.save()
  File "C:\Users\GOQii-BhushanP\anaconda3\envs\CementStregthDetection\lib\site-packages\pandas\io\formats\csvs.py", line 243, in save
    storage_options=self.storage_options,
  File "C:\Users\GOQii-BhushanP\anaconda3\envs\CementStregthDetection\lib\site-packages\pandas\io\common.py", line 707, in get_handle
    newline="",
FileNotFoundError: [Errno 2] No such file or directory: 'results/relevant_features_by_models.csv'
2022-01-12 08:02:07,316:ERROR:main:Defining a function "evaluate" to evaluate the performance metrics of a model
NoneType: None
2022-01-12 08:02:07,331:ERROR:main:Exception occurred in the function 'evaluate'. Exception message: adj_r2_score() takes 3 positional arguments but 4 were given
Traceback (most recent call last):
  File "C:/Users/GOQii-BhushanP/PycharmProjects/CementStregthDetection/main.py", line 125, in evaluate
    metrics.adj_r2_score(x_train, y_train, y_pred_train),
TypeError: adj_r2_score() takes 3 positional arguments but 4 were given
2022-01-12 08:02:07,365:ERROR:main:Exception occurred in the function 'rec_imp_features'. Exception message: [Errno 2] No such file or directory: 'results/relevant_features_by_models.csv'
Traceback (most recent call last):
  File "C:/Users/GOQii-BhushanP/PycharmProjects/CementStregthDetection/main.py", line 79, in rec_imp_features
    return dataframe.to_csv('results/relevant_features_by_models.csv', index=False)
  File "C:\Users\GOQii-BhushanP\anaconda3\envs\CementStregthDetection\lib\site-packages\pandas\core\generic.py", line 3482, in to_csv
    storage_options=storage_options,
  File "C:\Users\GOQii-BhushanP\anaconda3\envs\CementStregthDetection\lib\site-packages\pandas\io\formats\format.py", line 1105, in to_csv
    csv_formatter.save()
  File "C:\Users\GOQii-BhushanP\anaconda3\envs\CementStregthDetection\lib\site-packages\pandas\io\formats\csvs.py", line 243, in save
    storage_options=self.storage_options,
  File "C:\Users\GOQii-BhushanP\anaconda3\envs\CementStregthDetection\lib\site-packages\pandas\io\common.py", line 707, in get_handle
    newline="",
FileNotFoundError: [Errno 2] No such file or directory: 'results/relevant_features_by_models.csv'
2022-01-12 08:02:07,365:ERROR:main:Exception occurred in the function 'evaluate'. Exception message: adj_r2_score() takes 3 positional arguments but 4 were given
Traceback (most recent call last):
  File "C:/Users/GOQii-BhushanP/PycharmProjects/CementStregthDetection/main.py", line 125, in evaluate
    metrics.adj_r2_score(x_train, y_train, y_pred_train),
TypeError: adj_r2_score() takes 3 positional arguments but 4 were given
2022-01-12 08:02:07,414:ERROR:main:Exception occurred in the function 'rec_imp_features'. Exception message: [Errno 2] No such file or directory: 'results/relevant_features_by_models.csv'
Traceback (most recent call last):
  File "C:/Users/GOQii-BhushanP/PycharmProjects/CementStregthDetection/main.py", line 79, in rec_imp_features
    return dataframe.to_csv('results/relevant_features_by_models.csv', index=False)
  File "C:\Users\GOQii-BhushanP\anaconda3\envs\CementStregthDetection\lib\site-packages\pandas\core\generic.py", line 3482, in to_csv
    storage_options=storage_options,
  File "C:\Users\GOQii-BhushanP\anaconda3\envs\CementStregthDetection\lib\site-packages\pandas\io\formats\format.py", line 1105, in to_csv
    csv_formatter.save()
  File "C:\Users\GOQii-BhushanP\anaconda3\envs\CementStregthDetection\lib\site-packages\pandas\io\formats\csvs.py", line 243, in save
    storage_options=self.storage_options,
  File "C:\Users\GOQii-BhushanP\anaconda3\envs\CementStregthDetection\lib\site-packages\pandas\io\common.py", line 707, in get_handle
    newline="",
FileNotFoundError: [Errno 2] No such file or directory: 'results/relevant_features_by_models.csv'
2022-01-12 08:02:07,414:ERROR:main:Exception occurred in the function 'evaluate'. Exception message: adj_r2_score() takes 3 positional arguments but 4 were given
Traceback (most recent call last):
  File "C:/Users/GOQii-BhushanP/PycharmProjects/CementStregthDetection/main.py", line 125, in evaluate
    metrics.adj_r2_score(x_train, y_train, y_pred_train),
TypeError: adj_r2_score() takes 3 positional arguments but 4 were given
2022-01-12 08:02:07,489:ERROR:main:Exception occurred in the function 'rec_imp_features'. Exception message: [Errno 2] No such file or directory: 'results/relevant_features_by_models.csv'
Traceback (most recent call last):
  File "C:/Users/GOQii-BhushanP/PycharmProjects/CementStregthDetection/main.py", line 79, in rec_imp_features
    return dataframe.to_csv('results/relevant_features_by_models.csv', index=False)
  File "C:\Users\GOQii-BhushanP\anaconda3\envs\CementStregthDetection\lib\site-packages\pandas\core\generic.py", line 3482, in to_csv
    storage_options=storage_options,
  File "C:\Users\GOQii-BhushanP\anaconda3\envs\CementStregthDetection\lib\site-packages\pandas\io\formats\format.py", line 1105, in to_csv
    csv_formatter.save()
  File "C:\Users\GOQii-BhushanP\anaconda3\envs\CementStregthDetection\lib\site-packages\pandas\io\formats\csvs.py", line 243, in save
    storage_options=self.storage_options,
  File "C:\Users\GOQii-BhushanP\anaconda3\envs\CementStregthDetection\lib\site-packages\pandas\io\common.py", line 707, in get_handle
    newline="",
FileNotFoundError: [Errno 2] No such file or directory: 'results/relevant_features_by_models.csv'
2022-01-12 08:02:07,489:ERROR:main:Exception occurred in the function 'evaluate'. Exception message: adj_r2_score() takes 3 positional arguments but 4 were given
Traceback (most recent call last):
  File "C:/Users/GOQii-BhushanP/PycharmProjects/CementStregthDetection/main.py", line 125, in evaluate
    metrics.adj_r2_score(x_train, y_train, y_pred_train),
TypeError: adj_r2_score() takes 3 positional arguments but 4 were given
2022-01-12 08:02:10,234:ERROR:main:Exception occurred in the function 'rec_imp_features'. Exception message: [Errno 2] No such file or directory: 'results/relevant_features_by_models.csv'
Traceback (most recent call last):
  File "C:/Users/GOQii-BhushanP/PycharmProjects/CementStregthDetection/main.py", line 79, in rec_imp_features
    return dataframe.to_csv('results/relevant_features_by_models.csv', index=False)
  File "C:\Users\GOQii-BhushanP\anaconda3\envs\CementStregthDetection\lib\site-packages\pandas\core\generic.py", line 3482, in to_csv
    storage_options=storage_options,
  File "C:\Users\GOQii-BhushanP\anaconda3\envs\CementStregthDetection\lib\site-packages\pandas\io\formats\format.py", line 1105, in to_csv
    csv_formatter.save()
  File "C:\Users\GOQii-BhushanP\anaconda3\envs\CementStregthDetection\lib\site-packages\pandas\io\formats\csvs.py", line 243, in save
    storage_options=self.storage_options,
  File "C:\Users\GOQii-BhushanP\anaconda3\envs\CementStregthDetection\lib\site-packages\pandas\io\common.py", line 707, in get_handle
    newline="",
FileNotFoundError: [Errno 2] No such file or directory: 'results/relevant_features_by_models.csv'
2022-01-12 08:04:09,907:ERROR:main:Exception occurred in the function 'rec_imp_features'. Exception message: [Errno 2] No such file or directory: 'results/relevant_features_by_models.csv'
Traceback (most recent call last):
  File "C:/Users/GOQii-BhushanP/PycharmProjects/CementStregthDetection/main.py", line 79, in rec_imp_features
    return dataframe.to_csv('results/relevant_features_by_models.csv', index=False)
  File "C:\Users\GOQii-BhushanP\anaconda3\envs\CementStregthDetection\lib\site-packages\pandas\core\generic.py", line 3482, in to_csv
    storage_options=storage_options,
  File "C:\Users\GOQii-BhushanP\anaconda3\envs\CementStregthDetection\lib\site-packages\pandas\io\formats\format.py", line 1105, in to_csv
    csv_formatter.save()
  File "C:\Users\GOQii-BhushanP\anaconda3\envs\CementStregthDetection\lib\site-packages\pandas\io\formats\csvs.py", line 243, in save
    storage_options=self.storage_options,
  File "C:\Users\GOQii-BhushanP\anaconda3\envs\CementStregthDetection\lib\site-packages\pandas\io\common.py", line 707, in get_handle
    newline="",
FileNotFoundError: [Errno 2] No such file or directory: 'results/relevant_features_by_models.csv'
2022-01-12 08:04:09,913:ERROR:main:Defining a function "evaluate" to evaluate the performance metrics of a model
NoneType: None
2022-01-12 08:04:09,914:ERROR:main:Exception occurred in the function 'evaluate'. Exception message: adj_r2_score() takes 3 positional arguments but 4 were given
Traceback (most recent call last):
  File "C:/Users/GOQii-BhushanP/PycharmProjects/CementStregthDetection/main.py", line 125, in evaluate
    metrics.adj_r2_score(x_train, y_train, y_pred_train),
TypeError: adj_r2_score() takes 3 positional arguments but 4 were given
2022-01-12 08:04:09,966:ERROR:main:Exception occurred in the function 'rec_imp_features'. Exception message: [Errno 2] No such file or directory: 'results/relevant_features_by_models.csv'
Traceback (most recent call last):
  File "C:/Users/GOQii-BhushanP/PycharmProjects/CementStregthDetection/main.py", line 79, in rec_imp_features
    return dataframe.to_csv('results/relevant_features_by_models.csv', index=False)
  File "C:\Users\GOQii-BhushanP\anaconda3\envs\CementStregthDetection\lib\site-packages\pandas\core\generic.py", line 3482, in to_csv
    storage_options=storage_options,
  File "C:\Users\GOQii-BhushanP\anaconda3\envs\CementStregthDetection\lib\site-packages\pandas\io\formats\format.py", line 1105, in to_csv
    csv_formatter.save()
  File "C:\Users\GOQii-BhushanP\anaconda3\envs\CementStregthDetection\lib\site-packages\pandas\io\formats\csvs.py", line 243, in save
    storage_options=self.storage_options,
  File "C:\Users\GOQii-BhushanP\anaconda3\envs\CementStregthDetection\lib\site-packages\pandas\io\common.py", line 707, in get_handle
    newline="",
FileNotFoundError: [Errno 2] No such file or directory: 'results/relevant_features_by_models.csv'
2022-01-12 08:04:09,967:ERROR:main:Exception occurred in the function 'evaluate'. Exception message: adj_r2_score() takes 3 positional arguments but 4 were given
Traceback (most recent call last):
  File "C:/Users/GOQii-BhushanP/PycharmProjects/CementStregthDetection/main.py", line 125, in evaluate
    metrics.adj_r2_score(x_train, y_train, y_pred_train),
TypeError: adj_r2_score() takes 3 positional arguments but 4 were given
2022-01-12 08:04:10,018:ERROR:main:Exception occurred in the function 'rec_imp_features'. Exception message: [Errno 2] No such file or directory: 'results/relevant_features_by_models.csv'
Traceback (most recent call last):
  File "C:/Users/GOQii-BhushanP/PycharmProjects/CementStregthDetection/main.py", line 79, in rec_imp_features
    return dataframe.to_csv('results/relevant_features_by_models.csv', index=False)
  File "C:\Users\GOQii-BhushanP\anaconda3\envs\CementStregthDetection\lib\site-packages\pandas\core\generic.py", line 3482, in to_csv
    storage_options=storage_options,
  File "C:\Users\GOQii-BhushanP\anaconda3\envs\CementStregthDetection\lib\site-packages\pandas\io\formats\format.py", line 1105, in to_csv
    csv_formatter.save()
  File "C:\Users\GOQii-BhushanP\anaconda3\envs\CementStregthDetection\lib\site-packages\pandas\io\formats\csvs.py", line 243, in save
    storage_options=self.storage_options,
  File "C:\Users\GOQii-BhushanP\anaconda3\envs\CementStregthDetection\lib\site-packages\pandas\io\common.py", line 707, in get_handle
    newline="",
FileNotFoundError: [Errno 2] No such file or directory: 'results/relevant_features_by_models.csv'
2022-01-12 08:04:10,018:ERROR:main:Exception occurred in the function 'evaluate'. Exception message: adj_r2_score() takes 3 positional arguments but 4 were given
Traceback (most recent call last):
  File "C:/Users/GOQii-BhushanP/PycharmProjects/CementStregthDetection/main.py", line 125, in evaluate
    metrics.adj_r2_score(x_train, y_train, y_pred_train),
TypeError: adj_r2_score() takes 3 positional arguments but 4 were given
2022-01-12 08:04:10,131:ERROR:main:Exception occurred in the function 'rec_imp_features'. Exception message: [Errno 2] No such file or directory: 'results/relevant_features_by_models.csv'
Traceback (most recent call last):
  File "C:/Users/GOQii-BhushanP/PycharmProjects/CementStregthDetection/main.py", line 79, in rec_imp_features
    return dataframe.to_csv('results/relevant_features_by_models.csv', index=False)
  File "C:\Users\GOQii-BhushanP\anaconda3\envs\CementStregthDetection\lib\site-packages\pandas\core\generic.py", line 3482, in to_csv
    storage_options=storage_options,
  File "C:\Users\GOQii-BhushanP\anaconda3\envs\CementStregthDetection\lib\site-packages\pandas\io\formats\format.py", line 1105, in to_csv
    csv_formatter.save()
  File "C:\Users\GOQii-BhushanP\anaconda3\envs\CementStregthDetection\lib\site-packages\pandas\io\formats\csvs.py", line 243, in save
    storage_options=self.storage_options,
  File "C:\Users\GOQii-BhushanP\anaconda3\envs\CementStregthDetection\lib\site-packages\pandas\io\common.py", line 707, in get_handle
    newline="",
FileNotFoundError: [Errno 2] No such file or directory: 'results/relevant_features_by_models.csv'
2022-01-12 08:04:10,132:ERROR:main:Exception occurred in the function 'evaluate'. Exception message: adj_r2_score() takes 3 positional arguments but 4 were given
Traceback (most recent call last):
  File "C:/Users/GOQii-BhushanP/PycharmProjects/CementStregthDetection/main.py", line 125, in evaluate
    metrics.adj_r2_score(x_train, y_train, y_pred_train),
TypeError: adj_r2_score() takes 3 positional arguments but 4 were given
2022-01-12 08:04:13,297:ERROR:main:Exception occurred in the function 'rec_imp_features'. Exception message: [Errno 2] No such file or directory: 'results/relevant_features_by_models.csv'
Traceback (most recent call last):
  File "C:/Users/GOQii-BhushanP/PycharmProjects/CementStregthDetection/main.py", line 79, in rec_imp_features
    return dataframe.to_csv('results/relevant_features_by_models.csv', index=False)
  File "C:\Users\GOQii-BhushanP\anaconda3\envs\CementStregthDetection\lib\site-packages\pandas\core\generic.py", line 3482, in to_csv
    storage_options=storage_options,
  File "C:\Users\GOQii-BhushanP\anaconda3\envs\CementStregthDetection\lib\site-packages\pandas\io\formats\format.py", line 1105, in to_csv
    csv_formatter.save()
  File "C:\Users\GOQii-BhushanP\anaconda3\envs\CementStregthDetection\lib\site-packages\pandas\io\formats\csvs.py", line 243, in save
    storage_options=self.storage_options,
  File "C:\Users\GOQii-BhushanP\anaconda3\envs\CementStregthDetection\lib\site-packages\pandas\io\common.py", line 707, in get_handle
    newline="",
FileNotFoundError: [Errno 2] No such file or directory: 'results/relevant_features_by_models.csv'
2022-01-12 08:04:13,642:ERROR:main:Exception occurred in the function 'evaluate'. Exception message: adj_r2_score() takes 3 positional arguments but 4 were given
Traceback (most recent call last):
  File "C:/Users/GOQii-BhushanP/PycharmProjects/CementStregthDetection/main.py", line 125, in evaluate
    metrics.adj_r2_score(x_train, y_train, y_pred_train),
TypeError: adj_r2_score() takes 3 positional arguments but 4 were given
2022-01-12 08:04:13,642:ERROR:main:Exception occurred in the function 'rec_imp_features'. Exception message: [Errno 2] No such file or directory: 'results/relevant_features_by_models.csv'
Traceback (most recent call last):
  File "C:/Users/GOQii-BhushanP/PycharmProjects/CementStregthDetection/main.py", line 79, in rec_imp_features
    return dataframe.to_csv('results/relevant_features_by_models.csv', index=False)
  File "C:\Users\GOQii-BhushanP\anaconda3\envs\CementStregthDetection\lib\site-packages\pandas\core\generic.py", line 3482, in to_csv
    storage_options=storage_options,
  File "C:\Users\GOQii-BhushanP\anaconda3\envs\CementStregthDetection\lib\site-packages\pandas\io\formats\format.py", line 1105, in to_csv
    csv_formatter.save()
  File "C:\Users\GOQii-BhushanP\anaconda3\envs\CementStregthDetection\lib\site-packages\pandas\io\formats\csvs.py", line 243, in save
    storage_options=self.storage_options,
  File "C:\Users\GOQii-BhushanP\anaconda3\envs\CementStregthDetection\lib\site-packages\pandas\io\common.py", line 707, in get_handle
    newline="",
FileNotFoundError: [Errno 2] No such file or directory: 'results/relevant_features_by_models.csv'
2022-01-12 08:04:13,657:ERROR:main:Exception occurred in the function 'evaluate'. Exception message: adj_r2_score() takes 3 positional arguments but 4 were given
Traceback (most recent call last):
  File "C:/Users/GOQii-BhushanP/PycharmProjects/CementStregthDetection/main.py", line 125, in evaluate
    metrics.adj_r2_score(x_train, y_train, y_pred_train),
TypeError: adj_r2_score() takes 3 positional arguments but 4 were given
2022-01-12 08:04:39,391:ERROR:main:Exception occurred in the function 'rec_imp_features'. Exception message: [Errno 2] No such file or directory: 'results/relevant_features_by_models.csv'
Traceback (most recent call last):
  File "C:/Users/GOQii-BhushanP/PycharmProjects/CementStregthDetection/main.py", line 79, in rec_imp_features
    return dataframe.to_csv('results/relevant_features_by_models.csv', index=False)
  File "C:\Users\GOQii-BhushanP\anaconda3\envs\CementStregthDetection\lib\site-packages\pandas\core\generic.py", line 3482, in to_csv
    storage_options=storage_options,
  File "C:\Users\GOQii-BhushanP\anaconda3\envs\CementStregthDetection\lib\site-packages\pandas\io\formats\format.py", line 1105, in to_csv
    csv_formatter.save()
  File "C:\Users\GOQii-BhushanP\anaconda3\envs\CementStregthDetection\lib\site-packages\pandas\io\formats\csvs.py", line 243, in save
    storage_options=self.storage_options,
  File "C:\Users\GOQii-BhushanP\anaconda3\envs\CementStregthDetection\lib\site-packages\pandas\io\common.py", line 707, in get_handle
    newline="",
FileNotFoundError: [Errno 2] No such file or directory: 'results/relevant_features_by_models.csv'
2022-01-12 08:04:59,030:ERROR:main:Exception occurred in the function 'evaluate'. Exception message: adj_r2_score() takes 3 positional arguments but 4 were given
Traceback (most recent call last):
  File "C:/Users/GOQii-BhushanP/PycharmProjects/CementStregthDetection/main.py", line 125, in evaluate
    metrics.adj_r2_score(x_train, y_train, y_pred_train),
TypeError: adj_r2_score() takes 3 positional arguments but 4 were given
2022-01-12 09:07:32,192:ERROR:main:Exception occurred in the function 'rec_imp_features'. Exception message: [Errno 2] No such file or directory: 'results/relevant_features_by_models.csv'
Traceback (most recent call last):
  File "C:/Users/GOQii-BhushanP/PycharmProjects/CementStregthDetection/main.py", line 79, in rec_imp_features
    return dataframe.to_csv('results/relevant_features_by_models.csv', index=False)
  File "C:\Users\GOQii-BhushanP\anaconda3\envs\CementStregthDetection\lib\site-packages\pandas\core\generic.py", line 3482, in to_csv
    storage_options=storage_options,
  File "C:\Users\GOQii-BhushanP\anaconda3\envs\CementStregthDetection\lib\site-packages\pandas\io\formats\format.py", line 1105, in to_csv
    csv_formatter.save()
  File "C:\Users\GOQii-BhushanP\anaconda3\envs\CementStregthDetection\lib\site-packages\pandas\io\formats\csvs.py", line 243, in save
    storage_options=self.storage_options,
  File "C:\Users\GOQii-BhushanP\anaconda3\envs\CementStregthDetection\lib\site-packages\pandas\io\common.py", line 707, in get_handle
    newline="",
FileNotFoundError: [Errno 2] No such file or directory: 'results/relevant_features_by_models.csv'
2022-01-12 09:07:32,208:ERROR:main:Defining a function "evaluate" to evaluate the performance metrics of a model
NoneType: None
2022-01-12 09:07:32,208:ERROR:main:Exception occurred in the function 'evaluate'. Exception message: adj_r2_score() takes 3 positional arguments but 4 were given
Traceback (most recent call last):
  File "C:/Users/GOQii-BhushanP/PycharmProjects/CementStregthDetection/main.py", line 125, in evaluate
    metrics.adj_r2_score(x_train, y_train, y_pred_train),
TypeError: adj_r2_score() takes 3 positional arguments but 4 were given
2022-01-12 09:07:32,255:ERROR:main:Exception occurred in the function 'rec_imp_features'. Exception message: [Errno 2] No such file or directory: 'results/relevant_features_by_models.csv'
Traceback (most recent call last):
  File "C:/Users/GOQii-BhushanP/PycharmProjects/CementStregthDetection/main.py", line 79, in rec_imp_features
    return dataframe.to_csv('results/relevant_features_by_models.csv', index=False)
  File "C:\Users\GOQii-BhushanP\anaconda3\envs\CementStregthDetection\lib\site-packages\pandas\core\generic.py", line 3482, in to_csv
    storage_options=storage_options,
  File "C:\Users\GOQii-BhushanP\anaconda3\envs\CementStregthDetection\lib\site-packages\pandas\io\formats\format.py", line 1105, in to_csv
    csv_formatter.save()
  File "C:\Users\GOQii-BhushanP\anaconda3\envs\CementStregthDetection\lib\site-packages\pandas\io\formats\csvs.py", line 243, in save
    storage_options=self.storage_options,
  File "C:\Users\GOQii-BhushanP\anaconda3\envs\CementStregthDetection\lib\site-packages\pandas\io\common.py", line 707, in get_handle
    newline="",
FileNotFoundError: [Errno 2] No such file or directory: 'results/relevant_features_by_models.csv'
2022-01-12 09:07:32,255:ERROR:main:Exception occurred in the function 'evaluate'. Exception message: adj_r2_score() takes 3 positional arguments but 4 were given
Traceback (most recent call last):
  File "C:/Users/GOQii-BhushanP/PycharmProjects/CementStregthDetection/main.py", line 125, in evaluate
    metrics.adj_r2_score(x_train, y_train, y_pred_train),
TypeError: adj_r2_score() takes 3 positional arguments but 4 were given
2022-01-12 09:07:32,302:ERROR:main:Exception occurred in the function 'rec_imp_features'. Exception message: [Errno 2] No such file or directory: 'results/relevant_features_by_models.csv'
Traceback (most recent call last):
  File "C:/Users/GOQii-BhushanP/PycharmProjects/CementStregthDetection/main.py", line 79, in rec_imp_features
    return dataframe.to_csv('results/relevant_features_by_models.csv', index=False)
  File "C:\Users\GOQii-BhushanP\anaconda3\envs\CementStregthDetection\lib\site-packages\pandas\core\generic.py", line 3482, in to_csv
    storage_options=storage_options,
  File "C:\Users\GOQii-BhushanP\anaconda3\envs\CementStregthDetection\lib\site-packages\pandas\io\formats\format.py", line 1105, in to_csv
    csv_formatter.save()
  File "C:\Users\GOQii-BhushanP\anaconda3\envs\CementStregthDetection\lib\site-packages\pandas\io\formats\csvs.py", line 243, in save
    storage_options=self.storage_options,
  File "C:\Users\GOQii-BhushanP\anaconda3\envs\CementStregthDetection\lib\site-packages\pandas\io\common.py", line 707, in get_handle
    newline="",
FileNotFoundError: [Errno 2] No such file or directory: 'results/relevant_features_by_models.csv'
2022-01-12 09:07:32,302:ERROR:main:Exception occurred in the function 'evaluate'. Exception message: adj_r2_score() takes 3 positional arguments but 4 were given
Traceback (most recent call last):
  File "C:/Users/GOQii-BhushanP/PycharmProjects/CementStregthDetection/main.py", line 125, in evaluate
    metrics.adj_r2_score(x_train, y_train, y_pred_train),
TypeError: adj_r2_score() takes 3 positional arguments but 4 were given
2022-01-12 09:07:32,364:ERROR:main:Exception occurred in the function 'rec_imp_features'. Exception message: [Errno 2] No such file or directory: 'results/relevant_features_by_models.csv'
Traceback (most recent call last):
  File "C:/Users/GOQii-BhushanP/PycharmProjects/CementStregthDetection/main.py", line 79, in rec_imp_features
    return dataframe.to_csv('results/relevant_features_by_models.csv', index=False)
  File "C:\Users\GOQii-BhushanP\anaconda3\envs\CementStregthDetection\lib\site-packages\pandas\core\generic.py", line 3482, in to_csv
    storage_options=storage_options,
  File "C:\Users\GOQii-BhushanP\anaconda3\envs\CementStregthDetection\lib\site-packages\pandas\io\formats\format.py", line 1105, in to_csv
    csv_formatter.save()
  File "C:\Users\GOQii-BhushanP\anaconda3\envs\CementStregthDetection\lib\site-packages\pandas\io\formats\csvs.py", line 243, in save
    storage_options=self.storage_options,
  File "C:\Users\GOQii-BhushanP\anaconda3\envs\CementStregthDetection\lib\site-packages\pandas\io\common.py", line 707, in get_handle
    newline="",
FileNotFoundError: [Errno 2] No such file or directory: 'results/relevant_features_by_models.csv'
2022-01-12 09:07:32,364:ERROR:main:Exception occurred in the function 'evaluate'. Exception message: adj_r2_score() takes 3 positional arguments but 4 were given
Traceback (most recent call last):
  File "C:/Users/GOQii-BhushanP/PycharmProjects/CementStregthDetection/main.py", line 125, in evaluate
    metrics.adj_r2_score(x_train, y_train, y_pred_train),
TypeError: adj_r2_score() takes 3 positional arguments but 4 were given
2022-01-12 09:07:34,991:ERROR:main:Exception occurred in the function 'rec_imp_features'. Exception message: [Errno 2] No such file or directory: 'results/relevant_features_by_models.csv'
Traceback (most recent call last):
  File "C:/Users/GOQii-BhushanP/PycharmProjects/CementStregthDetection/main.py", line 79, in rec_imp_features
    return dataframe.to_csv('results/relevant_features_by_models.csv', index=False)
  File "C:\Users\GOQii-BhushanP\anaconda3\envs\CementStregthDetection\lib\site-packages\pandas\core\generic.py", line 3482, in to_csv
    storage_options=storage_options,
  File "C:\Users\GOQii-BhushanP\anaconda3\envs\CementStregthDetection\lib\site-packages\pandas\io\formats\format.py", line 1105, in to_csv
    csv_formatter.save()
  File "C:\Users\GOQii-BhushanP\anaconda3\envs\CementStregthDetection\lib\site-packages\pandas\io\formats\csvs.py", line 243, in save
    storage_options=self.storage_options,
  File "C:\Users\GOQii-BhushanP\anaconda3\envs\CementStregthDetection\lib\site-packages\pandas\io\common.py", line 707, in get_handle
    newline="",
FileNotFoundError: [Errno 2] No such file or directory: 'results/relevant_features_by_models.csv'
2022-01-12 09:07:35,288:ERROR:main:Exception occurred in the function 'evaluate'. Exception message: adj_r2_score() takes 3 positional arguments but 4 were given
Traceback (most recent call last):
  File "C:/Users/GOQii-BhushanP/PycharmProjects/CementStregthDetection/main.py", line 125, in evaluate
    metrics.adj_r2_score(x_train, y_train, y_pred_train),
TypeError: adj_r2_score() takes 3 positional arguments but 4 were given
2022-01-12 09:07:35,288:ERROR:main:Exception occurred in the function 'rec_imp_features'. Exception message: [Errno 2] No such file or directory: 'results/relevant_features_by_models.csv'
Traceback (most recent call last):
  File "C:/Users/GOQii-BhushanP/PycharmProjects/CementStregthDetection/main.py", line 79, in rec_imp_features
    return dataframe.to_csv('results/relevant_features_by_models.csv', index=False)
  File "C:\Users\GOQii-BhushanP\anaconda3\envs\CementStregthDetection\lib\site-packages\pandas\core\generic.py", line 3482, in to_csv
    storage_options=storage_options,
  File "C:\Users\GOQii-BhushanP\anaconda3\envs\CementStregthDetection\lib\site-packages\pandas\io\formats\format.py", line 1105, in to_csv
    csv_formatter.save()
  File "C:\Users\GOQii-BhushanP\anaconda3\envs\CementStregthDetection\lib\site-packages\pandas\io\formats\csvs.py", line 243, in save
    storage_options=self.storage_options,
  File "C:\Users\GOQii-BhushanP\anaconda3\envs\CementStregthDetection\lib\site-packages\pandas\io\common.py", line 707, in get_handle
    newline="",
FileNotFoundError: [Errno 2] No such file or directory: 'results/relevant_features_by_models.csv'
2022-01-12 09:07:35,288:ERROR:main:Exception occurred in the function 'evaluate'. Exception message: adj_r2_score() takes 3 positional arguments but 4 were given
Traceback (most recent call last):
  File "C:/Users/GOQii-BhushanP/PycharmProjects/CementStregthDetection/main.py", line 125, in evaluate
    metrics.adj_r2_score(x_train, y_train, y_pred_train),
TypeError: adj_r2_score() takes 3 positional arguments but 4 were given
2022-01-12 09:07:58,941:ERROR:main:Exception occurred in the function 'rec_imp_features'. Exception message: [Errno 2] No such file or directory: 'results/relevant_features_by_models.csv'
Traceback (most recent call last):
  File "C:/Users/GOQii-BhushanP/PycharmProjects/CementStregthDetection/main.py", line 79, in rec_imp_features
    return dataframe.to_csv('results/relevant_features_by_models.csv', index=False)
  File "C:\Users\GOQii-BhushanP\anaconda3\envs\CementStregthDetection\lib\site-packages\pandas\core\generic.py", line 3482, in to_csv
    storage_options=storage_options,
  File "C:\Users\GOQii-BhushanP\anaconda3\envs\CementStregthDetection\lib\site-packages\pandas\io\formats\format.py", line 1105, in to_csv
    csv_formatter.save()
  File "C:\Users\GOQii-BhushanP\anaconda3\envs\CementStregthDetection\lib\site-packages\pandas\io\formats\csvs.py", line 243, in save
    storage_options=self.storage_options,
  File "C:\Users\GOQii-BhushanP\anaconda3\envs\CementStregthDetection\lib\site-packages\pandas\io\common.py", line 707, in get_handle
    newline="",
FileNotFoundError: [Errno 2] No such file or directory: 'results/relevant_features_by_models.csv'
2022-01-12 09:08:15,503:ERROR:main:Exception occurred in the function 'evaluate'. Exception message: adj_r2_score() takes 3 positional arguments but 4 were given
Traceback (most recent call last):
  File "C:/Users/GOQii-BhushanP/PycharmProjects/CementStregthDetection/main.py", line 125, in evaluate
    metrics.adj_r2_score(x_train, y_train, y_pred_train),
TypeError: adj_r2_score() takes 3 positional arguments but 4 were given
2022-01-12 09:08:21,705:ERROR:main:Exception occurred in the function 'rec_imp_features'. Exception message: [Errno 2] No such file or directory: 'results/relevant_features_by_models.csv'
Traceback (most recent call last):
  File "C:/Users/GOQii-BhushanP/PycharmProjects/CementStregthDetection/main.py", line 79, in rec_imp_features
    return dataframe.to_csv('results/relevant_features_by_models.csv', index=False)
  File "C:\Users\GOQii-BhushanP\anaconda3\envs\CementStregthDetection\lib\site-packages\pandas\core\generic.py", line 3482, in to_csv
    storage_options=storage_options,
  File "C:\Users\GOQii-BhushanP\anaconda3\envs\CementStregthDetection\lib\site-packages\pandas\io\formats\format.py", line 1105, in to_csv
    csv_formatter.save()
  File "C:\Users\GOQii-BhushanP\anaconda3\envs\CementStregthDetection\lib\site-packages\pandas\io\formats\csvs.py", line 243, in save
    storage_options=self.storage_options,
  File "C:\Users\GOQii-BhushanP\anaconda3\envs\CementStregthDetection\lib\site-packages\pandas\io\common.py", line 707, in get_handle
    newline="",
FileNotFoundError: [Errno 2] No such file or directory: 'results/relevant_features_by_models.csv'
2022-01-12 09:08:28,375:ERROR:main:Exception occurred in the function 'evaluate'. Exception message: adj_r2_score() takes 3 positional arguments but 4 were given
Traceback (most recent call last):
  File "C:/Users/GOQii-BhushanP/PycharmProjects/CementStregthDetection/main.py", line 125, in evaluate
    metrics.adj_r2_score(x_train, y_train, y_pred_train),
TypeError: adj_r2_score() takes 3 positional arguments but 4 were given
2022-01-12 09:08:29,594:ERROR:main:Exception occurred in the function 'rec_imp_features'. Exception message: [Errno 2] No such file or directory: 'results/relevant_features_by_models.csv'
Traceback (most recent call last):
  File "C:/Users/GOQii-BhushanP/PycharmProjects/CementStregthDetection/main.py", line 79, in rec_imp_features
    return dataframe.to_csv('results/relevant_features_by_models.csv', index=False)
  File "C:\Users\GOQii-BhushanP\anaconda3\envs\CementStregthDetection\lib\site-packages\pandas\core\generic.py", line 3482, in to_csv
    storage_options=storage_options,
  File "C:\Users\GOQii-BhushanP\anaconda3\envs\CementStregthDetection\lib\site-packages\pandas\io\formats\format.py", line 1105, in to_csv
    csv_formatter.save()
  File "C:\Users\GOQii-BhushanP\anaconda3\envs\CementStregthDetection\lib\site-packages\pandas\io\formats\csvs.py", line 243, in save
    storage_options=self.storage_options,
  File "C:\Users\GOQii-BhushanP\anaconda3\envs\CementStregthDetection\lib\site-packages\pandas\io\common.py", line 707, in get_handle
    newline="",
FileNotFoundError: [Errno 2] No such file or directory: 'results/relevant_features_by_models.csv'
2022-01-12 09:08:30,843:ERROR:main:Exception occurred in the function 'evaluate'. Exception message: adj_r2_score() takes 3 positional arguments but 4 were given
Traceback (most recent call last):
  File "C:/Users/GOQii-BhushanP/PycharmProjects/CementStregthDetection/main.py", line 125, in evaluate
    metrics.adj_r2_score(x_train, y_train, y_pred_train),
TypeError: adj_r2_score() takes 3 positional arguments but 4 were given
2022-01-12 09:08:33,780:ERROR:main:Exception occurred in the function 'rec_imp_features'. Exception message: [Errno 2] No such file or directory: 'results/relevant_features_by_models.csv'
Traceback (most recent call last):
  File "C:/Users/GOQii-BhushanP/PycharmProjects/CementStregthDetection/main.py", line 79, in rec_imp_features
    return dataframe.to_csv('results/relevant_features_by_models.csv', index=False)
  File "C:\Users\GOQii-BhushanP\anaconda3\envs\CementStregthDetection\lib\site-packages\pandas\core\generic.py", line 3482, in to_csv
    storage_options=storage_options,
  File "C:\Users\GOQii-BhushanP\anaconda3\envs\CementStregthDetection\lib\site-packages\pandas\io\formats\format.py", line 1105, in to_csv
    csv_formatter.save()
  File "C:\Users\GOQii-BhushanP\anaconda3\envs\CementStregthDetection\lib\site-packages\pandas\io\formats\csvs.py", line 243, in save
    storage_options=self.storage_options,
  File "C:\Users\GOQii-BhushanP\anaconda3\envs\CementStregthDetection\lib\site-packages\pandas\io\common.py", line 707, in get_handle
    newline="",
FileNotFoundError: [Errno 2] No such file or directory: 'results/relevant_features_by_models.csv'
2022-01-12 09:08:36,889:ERROR:main:Exception occurred in the function 'evaluate'. Exception message: adj_r2_score() takes 3 positional arguments but 4 were given
Traceback (most recent call last):
  File "C:/Users/GOQii-BhushanP/PycharmProjects/CementStregthDetection/main.py", line 125, in evaluate
    metrics.adj_r2_score(x_train, y_train, y_pred_train),
TypeError: adj_r2_score() takes 3 positional arguments but 4 were given
2022-01-12 09:47:14,702:ERROR:main:Exception occurred in the function 'rec_imp_features'. Exception message: [Errno 2] No such file or directory: 'results/relevant_features_by_models.csv'
Traceback (most recent call last):
  File "C:/Users/GOQii-BhushanP/PycharmProjects/CementStregthDetection/main.py", line 79, in rec_imp_features
    return dataframe.to_csv('results/relevant_features_by_models.csv', index=False)
  File "C:\Users\GOQii-BhushanP\anaconda3\envs\CementStregthDetection\lib\site-packages\pandas\core\generic.py", line 3482, in to_csv
    storage_options=storage_options,
  File "C:\Users\GOQii-BhushanP\anaconda3\envs\CementStregthDetection\lib\site-packages\pandas\io\formats\format.py", line 1105, in to_csv
    csv_formatter.save()
  File "C:\Users\GOQii-BhushanP\anaconda3\envs\CementStregthDetection\lib\site-packages\pandas\io\formats\csvs.py", line 243, in save
    storage_options=self.storage_options,
  File "C:\Users\GOQii-BhushanP\anaconda3\envs\CementStregthDetection\lib\site-packages\pandas\io\common.py", line 707, in get_handle
    newline="",
FileNotFoundError: [Errno 2] No such file or directory: 'results/relevant_features_by_models.csv'
2022-01-12 09:47:14,708:ERROR:main:Defining a function "evaluate" to evaluate the performance metrics of a model
NoneType: None
2022-01-12 09:47:14,708:ERROR:main:Exception occurred in the function 'evaluate'. Exception message: adj_r2_score() takes 3 positional arguments but 4 were given
Traceback (most recent call last):
  File "C:/Users/GOQii-BhushanP/PycharmProjects/CementStregthDetection/main.py", line 125, in evaluate
    metrics.adj_r2_score(x_train, y_train, y_pred_train),
TypeError: adj_r2_score() takes 3 positional arguments but 4 were given
2022-01-12 09:47:14,755:ERROR:main:Exception occurred in the function 'rec_imp_features'. Exception message: [Errno 2] No such file or directory: 'results/relevant_features_by_models.csv'
Traceback (most recent call last):
  File "C:/Users/GOQii-BhushanP/PycharmProjects/CementStregthDetection/main.py", line 79, in rec_imp_features
    return dataframe.to_csv('results/relevant_features_by_models.csv', index=False)
  File "C:\Users\GOQii-BhushanP\anaconda3\envs\CementStregthDetection\lib\site-packages\pandas\core\generic.py", line 3482, in to_csv
    storage_options=storage_options,
  File "C:\Users\GOQii-BhushanP\anaconda3\envs\CementStregthDetection\lib\site-packages\pandas\io\formats\format.py", line 1105, in to_csv
    csv_formatter.save()
  File "C:\Users\GOQii-BhushanP\anaconda3\envs\CementStregthDetection\lib\site-packages\pandas\io\formats\csvs.py", line 243, in save
    storage_options=self.storage_options,
  File "C:\Users\GOQii-BhushanP\anaconda3\envs\CementStregthDetection\lib\site-packages\pandas\io\common.py", line 707, in get_handle
    newline="",
FileNotFoundError: [Errno 2] No such file or directory: 'results/relevant_features_by_models.csv'
2022-01-12 09:47:14,755:ERROR:main:Exception occurred in the function 'evaluate'. Exception message: adj_r2_score() takes 3 positional arguments but 4 were given
Traceback (most recent call last):
  File "C:/Users/GOQii-BhushanP/PycharmProjects/CementStregthDetection/main.py", line 125, in evaluate
    metrics.adj_r2_score(x_train, y_train, y_pred_train),
TypeError: adj_r2_score() takes 3 positional arguments but 4 were given
2022-01-12 09:47:14,805:ERROR:main:Exception occurred in the function 'rec_imp_features'. Exception message: [Errno 2] No such file or directory: 'results/relevant_features_by_models.csv'
Traceback (most recent call last):
  File "C:/Users/GOQii-BhushanP/PycharmProjects/CementStregthDetection/main.py", line 79, in rec_imp_features
    return dataframe.to_csv('results/relevant_features_by_models.csv', index=False)
  File "C:\Users\GOQii-BhushanP\anaconda3\envs\CementStregthDetection\lib\site-packages\pandas\core\generic.py", line 3482, in to_csv
    storage_options=storage_options,
  File "C:\Users\GOQii-BhushanP\anaconda3\envs\CementStregthDetection\lib\site-packages\pandas\io\formats\format.py", line 1105, in to_csv
    csv_formatter.save()
  File "C:\Users\GOQii-BhushanP\anaconda3\envs\CementStregthDetection\lib\site-packages\pandas\io\formats\csvs.py", line 243, in save
    storage_options=self.storage_options,
  File "C:\Users\GOQii-BhushanP\anaconda3\envs\CementStregthDetection\lib\site-packages\pandas\io\common.py", line 707, in get_handle
    newline="",
FileNotFoundError: [Errno 2] No such file or directory: 'results/relevant_features_by_models.csv'
2022-01-12 09:47:14,805:ERROR:main:Exception occurred in the function 'evaluate'. Exception message: adj_r2_score() takes 3 positional arguments but 4 were given
Traceback (most recent call last):
  File "C:/Users/GOQii-BhushanP/PycharmProjects/CementStregthDetection/main.py", line 125, in evaluate
    metrics.adj_r2_score(x_train, y_train, y_pred_train),
TypeError: adj_r2_score() takes 3 positional arguments but 4 were given
2022-01-12 09:47:14,856:ERROR:main:Exception occurred in the function 'rec_imp_features'. Exception message: [Errno 2] No such file or directory: 'results/relevant_features_by_models.csv'
Traceback (most recent call last):
  File "C:/Users/GOQii-BhushanP/PycharmProjects/CementStregthDetection/main.py", line 79, in rec_imp_features
    return dataframe.to_csv('results/relevant_features_by_models.csv', index=False)
  File "C:\Users\GOQii-BhushanP\anaconda3\envs\CementStregthDetection\lib\site-packages\pandas\core\generic.py", line 3482, in to_csv
    storage_options=storage_options,
  File "C:\Users\GOQii-BhushanP\anaconda3\envs\CementStregthDetection\lib\site-packages\pandas\io\formats\format.py", line 1105, in to_csv
    csv_formatter.save()
  File "C:\Users\GOQii-BhushanP\anaconda3\envs\CementStregthDetection\lib\site-packages\pandas\io\formats\csvs.py", line 243, in save
    storage_options=self.storage_options,
  File "C:\Users\GOQii-BhushanP\anaconda3\envs\CementStregthDetection\lib\site-packages\pandas\io\common.py", line 707, in get_handle
    newline="",
FileNotFoundError: [Errno 2] No such file or directory: 'results/relevant_features_by_models.csv'
2022-01-12 09:47:14,856:ERROR:main:Exception occurred in the function 'evaluate'. Exception message: adj_r2_score() takes 3 positional arguments but 4 were given
Traceback (most recent call last):
  File "C:/Users/GOQii-BhushanP/PycharmProjects/CementStregthDetection/main.py", line 125, in evaluate
    metrics.adj_r2_score(x_train, y_train, y_pred_train),
TypeError: adj_r2_score() takes 3 positional arguments but 4 were given
2022-01-12 09:47:17,692:ERROR:main:Exception occurred in the function 'rec_imp_features'. Exception message: [Errno 2] No such file or directory: 'results/relevant_features_by_models.csv'
Traceback (most recent call last):
  File "C:/Users/GOQii-BhushanP/PycharmProjects/CementStregthDetection/main.py", line 79, in rec_imp_features
    return dataframe.to_csv('results/relevant_features_by_models.csv', index=False)
  File "C:\Users\GOQii-BhushanP\anaconda3\envs\CementStregthDetection\lib\site-packages\pandas\core\generic.py", line 3482, in to_csv
    storage_options=storage_options,
  File "C:\Users\GOQii-BhushanP\anaconda3\envs\CementStregthDetection\lib\site-packages\pandas\io\formats\format.py", line 1105, in to_csv
    csv_formatter.save()
  File "C:\Users\GOQii-BhushanP\anaconda3\envs\CementStregthDetection\lib\site-packages\pandas\io\formats\csvs.py", line 243, in save
    storage_options=self.storage_options,
  File "C:\Users\GOQii-BhushanP\anaconda3\envs\CementStregthDetection\lib\site-packages\pandas\io\common.py", line 707, in get_handle
    newline="",
FileNotFoundError: [Errno 2] No such file or directory: 'results/relevant_features_by_models.csv'
2022-01-12 09:47:18,064:ERROR:main:Exception occurred in the function 'evaluate'. Exception message: adj_r2_score() takes 3 positional arguments but 4 were given
Traceback (most recent call last):
  File "C:/Users/GOQii-BhushanP/PycharmProjects/CementStregthDetection/main.py", line 125, in evaluate
    metrics.adj_r2_score(x_train, y_train, y_pred_train),
TypeError: adj_r2_score() takes 3 positional arguments but 4 were given
2022-01-12 09:47:18,064:ERROR:main:Exception occurred in the function 'rec_imp_features'. Exception message: [Errno 2] No such file or directory: 'results/relevant_features_by_models.csv'
Traceback (most recent call last):
  File "C:/Users/GOQii-BhushanP/PycharmProjects/CementStregthDetection/main.py", line 79, in rec_imp_features
    return dataframe.to_csv('results/relevant_features_by_models.csv', index=False)
  File "C:\Users\GOQii-BhushanP\anaconda3\envs\CementStregthDetection\lib\site-packages\pandas\core\generic.py", line 3482, in to_csv
    storage_options=storage_options,
  File "C:\Users\GOQii-BhushanP\anaconda3\envs\CementStregthDetection\lib\site-packages\pandas\io\formats\format.py", line 1105, in to_csv
    csv_formatter.save()
  File "C:\Users\GOQii-BhushanP\anaconda3\envs\CementStregthDetection\lib\site-packages\pandas\io\formats\csvs.py", line 243, in save
    storage_options=self.storage_options,
  File "C:\Users\GOQii-BhushanP\anaconda3\envs\CementStregthDetection\lib\site-packages\pandas\io\common.py", line 707, in get_handle
    newline="",
FileNotFoundError: [Errno 2] No such file or directory: 'results/relevant_features_by_models.csv'
2022-01-12 09:47:18,084:ERROR:main:Exception occurred in the function 'evaluate'. Exception message: adj_r2_score() takes 3 positional arguments but 4 were given
Traceback (most recent call last):
  File "C:/Users/GOQii-BhushanP/PycharmProjects/CementStregthDetection/main.py", line 125, in evaluate
    metrics.adj_r2_score(x_train, y_train, y_pred_train),
TypeError: adj_r2_score() takes 3 positional arguments but 4 were given
2022-01-12 09:47:44,109:ERROR:main:Exception occurred in the function 'rec_imp_features'. Exception message: [Errno 2] No such file or directory: 'results/relevant_features_by_models.csv'
Traceback (most recent call last):
  File "C:/Users/GOQii-BhushanP/PycharmProjects/CementStregthDetection/main.py", line 79, in rec_imp_features
    return dataframe.to_csv('results/relevant_features_by_models.csv', index=False)
  File "C:\Users\GOQii-BhushanP\anaconda3\envs\CementStregthDetection\lib\site-packages\pandas\core\generic.py", line 3482, in to_csv
    storage_options=storage_options,
  File "C:\Users\GOQii-BhushanP\anaconda3\envs\CementStregthDetection\lib\site-packages\pandas\io\formats\format.py", line 1105, in to_csv
    csv_formatter.save()
  File "C:\Users\GOQii-BhushanP\anaconda3\envs\CementStregthDetection\lib\site-packages\pandas\io\formats\csvs.py", line 243, in save
    storage_options=self.storage_options,
  File "C:\Users\GOQii-BhushanP\anaconda3\envs\CementStregthDetection\lib\site-packages\pandas\io\common.py", line 707, in get_handle
    newline="",
FileNotFoundError: [Errno 2] No such file or directory: 'results/relevant_features_by_models.csv'
2022-01-12 09:48:04,070:ERROR:main:Exception occurred in the function 'evaluate'. Exception message: adj_r2_score() takes 3 positional arguments but 4 were given
Traceback (most recent call last):
  File "C:/Users/GOQii-BhushanP/PycharmProjects/CementStregthDetection/main.py", line 125, in evaluate
    metrics.adj_r2_score(x_train, y_train, y_pred_train),
TypeError: adj_r2_score() takes 3 positional arguments but 4 were given
2022-01-12 09:48:11,788:ERROR:main:Exception occurred in the function 'rec_imp_features'. Exception message: [Errno 2] No such file or directory: 'results/relevant_features_by_models.csv'
Traceback (most recent call last):
  File "C:/Users/GOQii-BhushanP/PycharmProjects/CementStregthDetection/main.py", line 79, in rec_imp_features
    return dataframe.to_csv('results/relevant_features_by_models.csv', index=False)
  File "C:\Users\GOQii-BhushanP\anaconda3\envs\CementStregthDetection\lib\site-packages\pandas\core\generic.py", line 3482, in to_csv
    storage_options=storage_options,
  File "C:\Users\GOQii-BhushanP\anaconda3\envs\CementStregthDetection\lib\site-packages\pandas\io\formats\format.py", line 1105, in to_csv
    csv_formatter.save()
  File "C:\Users\GOQii-BhushanP\anaconda3\envs\CementStregthDetection\lib\site-packages\pandas\io\formats\csvs.py", line 243, in save
    storage_options=self.storage_options,
  File "C:\Users\GOQii-BhushanP\anaconda3\envs\CementStregthDetection\lib\site-packages\pandas\io\common.py", line 707, in get_handle
    newline="",
FileNotFoundError: [Errno 2] No such file or directory: 'results/relevant_features_by_models.csv'
2022-01-12 09:48:19,838:ERROR:main:Exception occurred in the function 'evaluate'. Exception message: adj_r2_score() takes 3 positional arguments but 4 were given
Traceback (most recent call last):
  File "C:/Users/GOQii-BhushanP/PycharmProjects/CementStregthDetection/main.py", line 125, in evaluate
    metrics.adj_r2_score(x_train, y_train, y_pred_train),
TypeError: adj_r2_score() takes 3 positional arguments but 4 were given
2022-01-12 09:48:21,402:ERROR:main:Exception occurred in the function 'rec_imp_features'. Exception message: [Errno 2] No such file or directory: 'results/relevant_features_by_models.csv'
Traceback (most recent call last):
  File "C:/Users/GOQii-BhushanP/PycharmProjects/CementStregthDetection/main.py", line 79, in rec_imp_features
    return dataframe.to_csv('results/relevant_features_by_models.csv', index=False)
  File "C:\Users\GOQii-BhushanP\anaconda3\envs\CementStregthDetection\lib\site-packages\pandas\core\generic.py", line 3482, in to_csv
    storage_options=storage_options,
  File "C:\Users\GOQii-BhushanP\anaconda3\envs\CementStregthDetection\lib\site-packages\pandas\io\formats\format.py", line 1105, in to_csv
    csv_formatter.save()
  File "C:\Users\GOQii-BhushanP\anaconda3\envs\CementStregthDetection\lib\site-packages\pandas\io\formats\csvs.py", line 243, in save
    storage_options=self.storage_options,
  File "C:\Users\GOQii-BhushanP\anaconda3\envs\CementStregthDetection\lib\site-packages\pandas\io\common.py", line 707, in get_handle
    newline="",
FileNotFoundError: [Errno 2] No such file or directory: 'results/relevant_features_by_models.csv'
2022-01-12 09:48:22,905:ERROR:main:Exception occurred in the function 'evaluate'. Exception message: adj_r2_score() takes 3 positional arguments but 4 were given
Traceback (most recent call last):
  File "C:/Users/GOQii-BhushanP/PycharmProjects/CementStregthDetection/main.py", line 125, in evaluate
    metrics.adj_r2_score(x_train, y_train, y_pred_train),
TypeError: adj_r2_score() takes 3 positional arguments but 4 were given
2022-01-12 09:48:26,372:ERROR:main:Exception occurred in the function 'rec_imp_features'. Exception message: [Errno 2] No such file or directory: 'results/relevant_features_by_models.csv'
Traceback (most recent call last):
  File "C:/Users/GOQii-BhushanP/PycharmProjects/CementStregthDetection/main.py", line 79, in rec_imp_features
    return dataframe.to_csv('results/relevant_features_by_models.csv', index=False)
  File "C:\Users\GOQii-BhushanP\anaconda3\envs\CementStregthDetection\lib\site-packages\pandas\core\generic.py", line 3482, in to_csv
    storage_options=storage_options,
  File "C:\Users\GOQii-BhushanP\anaconda3\envs\CementStregthDetection\lib\site-packages\pandas\io\formats\format.py", line 1105, in to_csv
    csv_formatter.save()
  File "C:\Users\GOQii-BhushanP\anaconda3\envs\CementStregthDetection\lib\site-packages\pandas\io\formats\csvs.py", line 243, in save
    storage_options=self.storage_options,
  File "C:\Users\GOQii-BhushanP\anaconda3\envs\CementStregthDetection\lib\site-packages\pandas\io\common.py", line 707, in get_handle
    newline="",
FileNotFoundError: [Errno 2] No such file or directory: 'results/relevant_features_by_models.csv'
2022-01-12 09:48:30,093:ERROR:main:Exception occurred in the function 'evaluate'. Exception message: adj_r2_score() takes 3 positional arguments but 4 were given
Traceback (most recent call last):
  File "C:/Users/GOQii-BhushanP/PycharmProjects/CementStregthDetection/main.py", line 125, in evaluate
    metrics.adj_r2_score(x_train, y_train, y_pred_train),
TypeError: adj_r2_score() takes 3 positional arguments but 4 were given
